Workbook

Sheet zestawienie
A1: stacja | B1: ilość | C1: długość
A2: 03-1341 | B2: ='03-1341'!H2 -> 21 | C2: ='03-1341'!H3 -> 630
A3: 03-0541 | B3: ='03-0541'!H2 -> 11 | C3: ='03-0541'!H3 -> 380
A4: 03-0664 | B4: ='03-0664'!H2 -> 35 | C4: ='03-0664'!H3 -> 1187
A5: 03-1250 | B5: ='03-1250'!H2 -> 20 | C5: ='03-1250'!H3 -> 569
A6: 03-0497 | B6: ='03-0497'!H2 -> 8 | C6: ='03-0497'!H3 -> 285
A7: 03-1336 | B7: ='03-1336'!H2 -> 3 | C7: ='03-1336'!H3 -> 85
A8: 03-0495 | B8: ='03-0495'!H2 -> 67 | C8: ='03-0495'!H3 -> 2769
A9: 03-1439 | B9: ='03-1439'!H2 -> 13 | C9: ='03-1439'!H3 -> 370
A10: 03-0494 | B10: ='03-0494'!H2 -> 39 | C10: ='03-0494'!H3 -> 1642
A11: 03-0496 | B11: ='03-0496'!H2 -> 25 | C11: ='03-0496'!H3 -> 927
A12: 03-1233 | B12: =#REF! -> #REF! | C12: =#REF! -> #REF!
B14: =SUM(B2:B12) -> #REF! | C14: =SUM(C2:C12) -> #REF!

Sheet 03-1341
A1: Nr słupa | B1: Oznaczenie | C1: Typ | D1: Odległość | E1: Mufa | F1: Obwód
A2: 1 | B2: P | C2: -12/10/E | D2: 21 | E2: - | F2: 1 | H2: =COUNT(A2:A27) -> 21
A3: 2 | B3: P | C3: -10/ZN | D3: 21 | E3: 1 | F3: 1 | H3: =SUM(D2:D27) -> 630
A4: 3 | B4: P | C4: -12/10/E | D4: 45 | E4: - | F4: 1
A5: 4 | B5: P | C5: -10/ZN | D5: 50 | E5: - | F5: 1
A6: 5 | B6: RPK | C6: -12/10/E | D6: 32 | E6: - | F6: 1
A7: 6 | B7: RPK | C7: -10,5/10/E | D7: 8 | E7: 1 | F7: 1
A8: 6.1 | B8: K | C8: -10,5/10/E | D8: 18 | E8: - | F8: 1
A9: 7 | B9: P | C9: -10/ZN | D9: 49 | E9: - | F9: 1
A10: 8 | B10: P | C10: -10/ZN | D10: 26 | E10: - | F10: 1
A11: 1 | B11: P | C11: -10/ZN | D11: 21 | E11: - | F11: 2
A12: 2 | B12: N | C12: -10,5/10/E | D12: 23 | E12: 1 | F12: 2
A13: 3 | B13: N | C13: -10,5/10/E | D13: 22 | E13: - | F13: 2
A14: 4 | B14: N | C14: -10,5/10/E | D14: 23 | E14: - | F14: 2
A15: 5 | B15: P | C15: -10/ZN | D15: 40 | E15: - | F15: 2
A16: 6 | B16: P | C16: -10/ZN | D16: 49 | E16: - | F16: 2
A17: 7 | B17: N | C17: -10,5/10/E | D17: 29 | E17: 1 | F17: 2
A18: 8 | B18: P | C18: -10/ZN | D18: 33 | E18: - | F18: 2
A19: 9 | B19: K | C19: -10,5/10/E | D19: 32 | E19: - | F19: 2
A20: 10 | B20: RPK | C20: -10,5/10/E | D20: 22 | E20: - | F20: 2
A21: 11 | B21: P | C21: -10/ZN | D21: 22 | E21: - | F21: 2
A22: 12 | B22: P | C22: -10/ZN | D22: 44 | E22: - | F22: 2

Sheet 03-0541
A1: Nr słupa | B1: Oznaczenie | C1: Typ | D1: Odległość | E1: Mufa | F1: Obwód
A2: 1 | B2: Nr | C2: -10/ZN | D2: 22 | E2: 1 | F2: 1 | H2: =COUNT(A2:A27) -> 11
A3: 2 | B3: P | C3: -10/ZN | D3: 22 | E3: - | F3: 1 | H3: =SUM(D2:D27) -> 380
A4: 3 | B4: P | C4: -10/ZN | D4: 48 | E4: - | F4: 1
A5: 4 | B5: P | C5: -10/ZN | D5: 48 | E5: - | F5: 1
A6: 5 | B6: P | C6: -10/ZN | D6: 41 | E6: - | F6: 1
A7: 6 | B7: RPKr | C7: -10/ZN | D7: 32 | E7: 1 | F7: 1
A8: 7 | B8: P | C8: -10/ZN | D8: 38 | E8: - | F8: 1
A9: 8 | B9: P | C9: -10/ZN | D9: 38 | E9: - | F9: 1
A10: 9 | B10: P | C10: -10/ZN | D10: 22 | E10: - | F10: 1
A11: 10 | B11: P | C11: -10/ZN | D11: 23 | E11: - | F11: 1
A12: 11 | B12: Kr | C12: -10/ZN | D12: 46 | E12: - | F12: 1

Sheet 03-0664
A1: Nr słupa | B1: Oznaczenie | C1: Typ | D1: Odległość | E1: Mufa | F1: Obwód
A2: 1 | B2: P | C2: -10/ZN | D2: 18 | E2: - | F2: 1 | H2: =COUNT(A2:A36) -> 35
A3: 2 | B3: P | C3: -10/ZN | D3: 18 | E3: - | F3: 1 | H3: =SUM(D2:D36) -> 1187
A4: 3 | B4: RPKr | C4: -10/ZN | D4: 22 | E4: - | F4: 1
A5: 3.1 | B5: P | C5: -10/ZN | D5: 23 | E5: - | F5: 1
A6: 3.2 | B6: P | C6: -10/ZN | D6: 22 | E6: - | F6: 1
A7: 3.3 | B7: Kr | C7: -10/ZN | D7: 22 | E7: - | F7: 1
A8: 4 | B8: RPKr | C8: -10/ZN | D8: 23 | E8: - | F8: 1
A9: 5 | B9: P | C9: -10/ZN | D9: 47 | E9: - | F9: 1
A10: 6 | B10: P | C10: -10/ZN | D10: 43 | E10: - | F10: 1
A11: 7 | B11: P | C11: -10/ZN | D11: 41 | E11: 1 | F11: 1
A12: 8 | B12: P | C12: -10/ZN | D12: 43 | E12: - | F12: 1
A13: 9 | B13: P | C13: -10/ZN | D13: 43 | E13: 1 | F13: 1
A14: 10 | B14: RPKr | C14: -10/ZN | D14: 16 | E14: - | F14: 1
A15: 11 | B15: P | C15: -10/ZN | D15: 45 | E15: - | F15: 1
A16: 12 | B16: Nb | C16: -12/10/E | D16: 19 | E16: - | F16: 1
A17: 13 | B17: RPK | C17: -12/10/E | D17: 28 | E17: 1 | F17: 1
A18: 14 | B18: P | C18: -10,5/10/E | D18: 31 | E18: - | F18: 1
A19: 15 | B19: P | C19: -10,5/10/E | D19: 33 | E19: - | F19: 1
A20: 16 | B20: N | C20: -10,5/10/E | D20: 32 | E20: - | F20: 1
A21: 17 | B21: RPK | C21: -10,5/10/E | D21: 18 | E21: 1 | F21: 1
A22: 17.1 | B22: N | C22: -10,5/10/E | D22: 7 | E22: - | F22: 1
A23: 17.2 | B23: P | C23: -10/ZN | D23: 52 | E23: - | F23: 1
A24: 17.3 | B24: P | C24: -10/ZN | D24: 56 | E24: 1 | F24: 1
A25: 17.4 | B25: K | C25: -10,5/10/E | D25: 56 | E25: - | F25: 1
A26: 18 | B26: P | C26: -10/ZN | D26: 52 | E26: - | F26: 1
A27: 19 | B27: P | C27: -10/ZN | D27: 45 | E27: - | F27: 1
A28: 20 | B28: RPK | C28: -10,5/10/E | D28: 46 | E28: 1 | F28: 1
A29: 21 | B29: P | C29: -10/ZN | D29: 37 | E29: - | F29: 1
A30: 22 | B30: K | C30: -10,5/10/E | D30: 50 | E30: 1 | F30: 1
A31: 21 | B31: RPK | C31: -10,5/10/E | D31: 49 | E31: - | F31: 1
A32: 21.1 | B32: K | C32: -10,5/10/E | D32: 19 | E32: - | F32: 1
A33: 22 | B33: P | C33: -10/ZN | D33: 31 | E33: - | F33: 1
A34: 23 | B34: P | C34: -10/ZN | D34: 32 | E34: - | F34: 1
A35: 24 | B35: P | C35: -10/ZN | D35: 25 | E35: 1 | F35: 1
A36: 25 | B36: K | C36: -10,5/10/E | D36: 43 | E36: - | F36: 1

Sheet 03-1250
A1: Nr słupa | B1: Oznaczenie | C1: Typ | D1: Odległość | E1: Mufa | F1: Obwód
A2: 1 | B2: P | C2: -10/ZN | D2: 20 | E2: - | F2: 1 | H2: =COUNT(A2:A36) -> 20
A3: 2 | B3: P | C3: -10/ZN | D3: 31 | E3: 1 | F3: 1 | H3: =SUM(D2:D36) -> 569
A4: 3 | B4: P | C4: -12/10/E | D4: 32 | E4: - | F4: 1
A5: 4 | B5: P | C5: -10/ZN | D5: 22 | E5: 1 | F5: 1
A6: 5 | B6: P | C6: -12/10/E | D6: 26 | E6: - | F6: 1
A7: 6 | B7: P | C7: -10/ZN | D7: 24 | E7: - | F7: 1
A8: 7 | B8: Kb | C8: -12/10/E | D8: 25 | E8: 1 | F8: 1
A9: 1 | B9: P | C9: -10/ZN | D9: 16 | E9: - | F9: 2
A10: 2 | B10: P | C10: -10/ZN | D10: 17 | E10: - | F10: 2
A11: 3 | B11: RPK | C11: -10,5/10/E | D11: 33 | E11: 1 | F11: 2
A12: 3.1 | B12: N | C12: -10,5/10/E | D12: 16 | E12: - | F12: 2
A13: 3.2 | B13: K | C13: -10,5/10/E | D13: 35 | E13: - | F13: 2
A14: 4 | B14: P | C14: -10/ZN | D14: 35 | E14: - | F14: 2
A15: 5 | B15: N | C15: -10,5/10/E | D15: 36 | E15: 1 | F15: 2
A16: 6 | B16: P | C16: -10/ZN | D16: 28 | E16: - | F16: 2
A17: 7 | B17: RPK | C17: -10,5/10/E | D17: 37 | E17: 1 | F17: 2
A18: 8 | B18: N | C18: -10,5/10/E | D18: 22 | E18: - | F18: 2
A19: 9 | B19: N | C19: -10,5/10/E | D19: 14 | E19: - | F19: 2
A20: 10 | B20: P | C20: -10/ZN | D20: 46 | E20: - | F20: 2
A21: 11 | B21: K | C21: -10,5/10/E | D21: 54 | E21: 1 | F21: 2

Sheet 03-0497
A1: Nr słupa | B1: Oznaczenie | C1: Typ | D1: Odległość | E1: Mufa | F1: Obwód
A2: 1 | B2: RPKr | C2: -10/ZN | D2: 26 | E2: - | F2: 1 | H2: =COUNT(A2:A36) -> 8
A3: 2 | B3: P | C3: -10/ZN | D3: 27 | E3: - | F3: 1 | H3: =SUM(D2:D36) -> 285
A4: 3 | B4: RPKr | C4: -10/ZN | D4: 46 | E4: 1 | F4: 1
A5: 4 | B5: P | C5: -10/ZN | D5: 55 | E5: - | F5: 1
A6: 5 | B6: N | C6: -10,5/10/E | D6: 27 | E6: - | F6: 1
A7: 6 | B7: K | C7: -10,5/10/E | D7: 53 | E7: - | F7: 1
A8: 7 | B8: P | C8: -10,5/10/E | D8: 25 | E8: - | F8: 1
A9: 8 | B9: RPK | C9: -10,5/10/E | D9: 26 | E9: 1 | F9: 1

Sheet 03-1336
A1: Nr słupa | B1: Oznaczenie | C1: Typ | D1: Odległość | E1: Mufa | F1: Obwód
A2: 1 | B2: P | C2: -10/ZN | D2: 21 | E2: 1 | F2: 1 | H2: =COUNT(A2:A36) -> 3
A3: 2 | B3: P | C3: -10/ZN | D3: 22 | E3: - | F3: 1 | H3: =SUM(D2:D36) -> 85
A4: 3 | B4: K | C4: -10,5/10/E | D4: 42 | E4: - | F4: 1

Sheet 03-0495
A1: Nr słupa | B1: Oznaczenie | C1: Typ | D1: Odległość | E1: Mufa | F1: Obwód
A2: 1 | B2: P | C2: -10/ZN | D2: 23 | E2: - | F2: 1 | H2: =COUNT(A2:A68) -> 67
A3: 2 | B3: P | C3: -10/ZN | D3: 24 | E3: - | F3: 1 | H3: =SUM(D2:D68) -> 2769
A4: 3 | B4: RPK | C4: -10,5/10/E | D4: 22 | E4: 1 | F4: 1
A5: 3.1 | B5: Nr | C5: -10/ZN | D5: 17 | E5: - | F5: 1
A6: 3.2 | B6: P | C6: -10/ZN | D6: 42 | E6: - | F6: 1
A7: 3.3 | B7: P | C7: -10/ZN | D7: 41 | E7: - | F7: 1
A8: 3.4 | B8: K | C8: -10,5/10/E | D8: 46 | E8: - | F8: 1
A9: 4 | B9: P | C9: -10/ZN | D9: 24 | E9: - | F9: 1
A10: 5 | B10: RPKr | C10: -10/ZN | D10: 50 | E10: 1 | F10: 1
A11: 5.1 | B11: P | C11: -10/ZN | D11: 53 | E11: - | F11: 1
A12: 5.2 | B12: P | C12: -10/ZN | D12: 52 | E12: - | F12: 1
A13: 5.3 | B13: Nr | C13: -10/ZN | D13: 54 | E13: 1 | F13: 1
A14: 5.4 | B14: Nr | C14: -10/ZN | D14: 44 | E14: - | F14: 1
A15: 5.5 | B15: P | C15: -10/ZN | D15: 46 | E15: 1 | F15: 1
A16: 5.6 | B16: P | C16: -10/ZN | D16: 54 | E16: - | F16: 1
A17: 5.7 | B17: P | C17: -10/ZN | D17: 45 | E17: - | F17: 1
A18: 5.8 | B18: P | C18: -10/ZN | D18: 53 | E18: 1 | F18: 1
A19: 5.9 | B19: Kr | C19: -10/ZN | D19: 57 | E19: - | F19: 1
A20: 6 | B20: Nr | C20: -10/ZN | D20: 53 | E20: - | F20: 1
A21: 7 | B21: N | C21: -10,5/10/E | D21: 34 | E21: - | F21: 1
A22: 8 | B22: P | C22: -10/ZN | D22: 42 | E22: - | F22: 1
A23: 9 | B23: P | C23: -10/ZN | D23: 33 | E23: - | F23: 1
A24: 10 | B24: RPK | C24: -10,5/10/E | D24: 35 | E24: 1 | F24: 1
A25: 10.1 | B25: P | C25: -10/ZN | D25: 35 | E25: - | F25: 1
A26: 10.2 | B26: K | C26: -10,5/10/E | D26: 38 | E26: - | F26: 1
A27: 11 | B27: P | C27: -10/ZN | D27: 40 | E27: - | F27: 1
A28: 12 | B28: N | C28: -10.5/10/E | D28: 37 | E28: - | F28: 1
A29: 13 | B29: N | C29: -10/ZN | D29: 6 | E29: 1 | F29: 1
A30: 14 | B30: K | C30: -10/ZN | D30: 44 | E30: - | F30: 1
A31: 1 | B31: P | C31: -10/ZN | D31: 15 | E31: 1 | F31: 2
A32: 2 | B32: Nr | C32: -10/ZN | D32: 16 | E32: - | F32: 2
A33: 3 | B33: P | C33: -10/ZN | D33: 46 | E33: - | F33: 2
A34: 4 | B34: P | C34: -10/ZN | D34: 38 | E34: - | F34: 2
A35: 5 | B35: Or | C35: -10/ZN | D35: 52 | E35: 1 | F35: 2
A36: 6 | B36: RPKr | C36: -10/ZN | D36: 47 | E36: - | F36: 2
A37: 7 | B37: P | C37: -10/ZN | D37: 28 | E37: - | F37: 2
A38: 1 | B38: P | C38: -10/ZN | D38: 42 | E38: - | F38: 3
A39: 2 | B39: P | C39: -10/ZN | D39: 33 | E39: - | F39: 3
A40: 3 | B40: Or | C40: -10/ZN | D40: 30 | E40: - | F40: 3
...

Sheet 03-1439
A1: Nr słupa | B1: Oznaczenie | C1: Typ | D1: Odległość | E1: Mufa | F1: Obwód
A2: 1 | B2: K | C2: -10,5/10/E | D2: 17 | E2: - | F2: 1 | H2: =COUNT(A2:A39) -> 13
A3: 2 | B3: N | C3: -10,5/10/E | D3: 17 | E3: - | F3: 1 | H3: =SUM(D2:D39) -> 370
A4: 3 | B4: P | C4: -10/ZN | D4: 20 | E4: - | F4: 1
A5: 3.1 | B5: P | C5: -10/ZN | D5: 14 | E5: - | F5: 1
A6: 4 | B6: P | C6: -10/ZN | D6: 20 | E6: - | F6: 1
A7: 5 | B7: P | C7: -10/ZN | D7: 40 | E7: 1 | F7: 1
A8: 6 | B8: P | C8: -10/ZN | D8: 35 | E8: - | F8: 1
A9: 7 | B9: RPKb | C9: -10/ZN | D9: 35 | E9: 1 | F9: 1
A10: 7.1 | B10: N | C10: -10,5/10/E | D10: 8 | E10: - | F10: 1
A11: 7.2 | B11: P | C11: -10/ZN | D11: 46 | E11: - | F11: 1
A12: 7.3 | B12: K | C12: -10,5/10/E | D12: 45 | E12: 1 | F12: 1
A13: 8 | B13: P | C13: -10/ZN | D13: 36 | E13: - | F13: 1
A14: 9 | B14: P | C14: -10/ZN | D14: 37 | E14: - | F14: 1

Sheet 03-0494
A1: Nr słupa | B1: Oznaczenie | C1: Typ | D1: Odległość | E1: Mufa | F1: Obwód
A2: 1 | B2: P | C2: -10/ZN | D2: 26 | E2: - | F2: 1 | H2: =COUNT(A2:A40) -> 39
A3: 2 | B3: RPKr | C3: -10/ZN | D3: 27 | E3: - | F3: 1 | H3: =SUM(D2:D40) -> 1642
A4: 3 | B4: P | C4: -10/ZN | D4: 47 | E4: - | F4: 1
A5: 4 | B5: P | C5: -10/ZN | D5: 50 | E5: - | F5: 1
A6: 5 | B6: RPKr | C6: -10/ZN | D6: 50 | E6: 1 | F6: 1
A7: 5.1 | B7: RPKr | C7: -10/ZN | D7: 49 | E7: 1 | F7: 1
A8: 5.2 | B8: P | C8: -10/ZN | D8: 52 | E8: - | F8: 1
A9: 5.3 | B9: Kr | C9: -10/ZN | D9: 51 | E9: - | F9: 1
A10: 5.4 | B10: N | C10: -10,5/10/E | D10: 26 | E10: - | F10: 1
A11: 5.5 | B11: N | C11: -10,5/10/E | D11: 13 | E11: - | F11: 1
A12: 5.6 | B12: RPK | C12: -10,5/10/E | D12: 8 | E12: 1 | F12: 1
A13: 5.7 | B13: Nr | C13: -10/ZN | D13: 52 | E13: - | F13: 1
A14: 6 | B14: Nr | C14: -10/ZN | D14: 46 | E14: - | F14: 1
A15: 7 | B15: P | C15: -10/ZN | D15: 55 | E15: - | F15: 1
A16: 8 | B16: P | C16: -10/ZN | D16: 53 | E16: - | F16: 1
A17: 9 | B17: RPKr | C17: -10/ZN | D17: 49 | E17: - | F17: 1
A18: 10 | B18: P | C18: -10/ZN | D18: 51 | E18: - | F18: 1
A19: 11 | B19: P | C19: -10/ZN | D19: 41 | E19: - | F19: 1
A20: 12 | B20: P | C20: -10/ZN | D20: 44 | E20: - | F20: 1
A21: 13 | B21: Nr | C21: -10/ZN | D21: 44 | E21: 1 | F21: 1
A22: 14 | B22: P | C22: -10/ZN | D22: 40 | E22: - | F22: 1
A23: 15 | B23: Nr | C23: -10/ZN | D23: 42 | E23: - | F23: 1
A24: 16 | B24: N | C24: -10,5/10/E | D24: 51 | E24: 1 | F24: 1
A25: 17 | B25: P | C25: -10/ZN | D25: 39 | E25: - | F25: 1
A26: 18 | B26: Kr | C26: -10,5/10/E | D26: 37 | E26: - | F26: 1
A27: 1 | B27: Nr | C27: -10/ZN | D27: 12 | E27: 1 | F27: 2
A28: 2 | B28: P | C28: -10/ZN | D28: 51 | E28: - | F28: 2
A29: 3 | B29: RPKr | C29: -10/ZN | D29: 51 | E29: 1 | F29: 2
A30: 4 | B30: P | C30: -10/ZN | D30: 45 | E30: - | F30: 2
A31: 5 | B31: P | C31: -10/ZN | D31: 50 | E31: - | F31: 2
A32: 6 | B32: P | C32: -10/ZN | D32: 50 | E32: 1 | F32: 2
A33: 7 | B33: P | C33: -10/ZN | D33: 51 | E33: - | F33: 2
A34: 8 | B34: P | C34: -10/ZN | D34: 43 | E34: - | F34: 2
A35: 9 | B35: Kr | C35: -10/ZN | D35: 54 | E35: 1 | F35: 2
A36: 1 | B36: RPKr | C36: -10/ZN | D36: 12 | E36: - | F36: 3
A37: 2 | B37: RPKr | C37: -10/ZN | D37: 37 | E37: 1 | F37: 3
A38: 3 | B38: P | C38: -10/ZN | D38: 50 | E38: - | F38: 3
A39: 4 | B39: P | C39: -10/ZN | D39: 49 | E39: - | F39: 3
A40: 5 | B40: K | C40: -10,5/10/E | D40: 44 | E40: 1 | F40: 3

Sheet 03-0496
A1: Nr słupa | B1: Oznaczenie | C1: Typ | D1: Odległość | E1: Mufa | F1: Obwód
A2: 1 | B2: P | C2: -10/ZN | D2: 24 | E2: - | F2: 1 | H2: =COUNT(A2:A39) -> 25
A3: 2 | B3: P | C3: -10/ZN | D3: 24 | E3: - | F3: 1 | H3: =SUM(D2:D39) -> 927
A4: 3 | B4: P | C4: -10/ZN | D4: 50 | E4: - | F4: 1
A5: 4 | B5: P | C5: -10/ZN | D5: 49 | E5: 1 | F5: 1
A6: 5 | B6: P | C6: -10/ZN | D6: 50 | E6: - | F6: 1
A7: 6 | B7: P | C7: -10/ZN | D7: 51 | E7: - | F7: 1
A8: 7 | B8: P | C8: -10/ZN | D8: 49 | E8: - | F8: 1
A9: 8 | B9: RPK | C9: -10,5/10/E | D9: 23 | E9: 1 | F9: 1
A10: 8.1 | B10: Nr | C10: -10/ZN | D10: 16 | E10: - | F10: 1
A11: 8.2 | B11: K | C11: -10,5/10/E | D11: 42 | E11: - | F11: 1
A12: 9 | B12: P | C12: -10/ZN | D12: 26 | E12: - | F12: 1
A13: 10 | B13: P | C13: -10/ZN | D13: 43 | E13: - | F13: 1
A14: 11 | B14: P | C14: -10/ZN | D14: 39 | E14: - | F14: 1
A15: 12 | B15: Kr | C15: -10/ZN | D15: 37 | E15: 1 | F15: 1
A16: 1 | B16: P | C16: -10/ZN | D16: 25 | E16: - | F16: 2
A17: 2 | B17: P | C17: -10/ZN | D17: 24 | E17: - | F17: 2
A18: 3 | B18: RPKr | C18: -10/ZN | D18: 52 | E18: 1 | F18: 2
A19: 4 | B19: P | C19: -10/ZN | D19: 50 | E19: - | F19: 2
A20: 5 | B20: RPK | C20: -10,5/10/E | D20: 24 | E20: 1 | F20: 2
A21: 5.1 | B21: P | C21: -10/ZN | D21: 17 | E21: - | F21: 2
A22: 5.2 | B22: K | C22: -10,5/10/E | D22: 48 | E22: - | F22: 2
A23: 6 | B23: N | C23: -10,5/10/E | D23: 27 | E23: - | F23: 2
A24: 7 | B24: P | C24: -10/ZN | D24: 50 | E24: - | F24: 2
A25: 8 | B25: P | C25: -10/ZN | D25: 50 | E25: - | F25: 2
A26: 9 | B26: K | C26: -10,5/10/E | D26: 37 | E26: 1 | F26: 2

Sheet 03-1233
A1: Nr słupa | B1: Oznaczenie | C1: Typ | D1: Odległość | E1: Mufa | F1: Obwód
A2: 1 | B2: N | C2: -10,5/10/E | D2: 11 | E2: - | F2: 1 | H2: =COUNT(D2:D163) -> 73
A3: 2 | B3: RPK | C3: -10,5/10/E | D3: 11 | E3: - | F3: 1 | H3: =SUM(D2:D74) -> 2509
A4: 3 | B4: N | C4: -10,5/10/E | D4: 31 | E4: - | F4: 1
A5: 4 | B5: RPK | C5: -10,5/10/E | D5: 43 | E5: 1 | F5: 1
A6: 4.1 | B6: N | C6: -10,5/10/E | D6: 25 | E6: - | F6: 1
A7: 4.2 | B7: N | C7: -10,5/10/E | D7: 43 | E7: - | F7: 1
A8: 4.3 | B8: N | C8: -10,5/10/E | D8: 6 | E8: - | F8: 1
A9: 4.4 | B9: P | C9: -10/ZN | D9: 33 | E9: - | F9: 1
A10: 4.5 | B10: P | C10: -10/ZN | D10: 34 | E10: - | F10: 1
A11: 4.6 | B11: Kr | C11: -10,5/10/E | D11: 44 | E11: 1 | F11: 1
A12: 5 | B12: P | C12: -10/ZN | D12: 46 | E12: - | F12: 1
A13: 6 | B13: N | C13: -10,5/10/E | D13: 29 | E13: - | F13: 1
A14: 7 | B14: P | C14: -10/ZN | D14: 35 | E14: 1 | F14: 1
A15: 8 | B15: P | C15: -10/ZN | D15: 36 | E15: - | F15: 1
A16: 9 | B16: P | C16: -10/ZN | D16: 35 | E16: - | F16: 1
A17: 10 | B17: P | C17: -10/ZN | D17: 40 | E17: 1 | F17: 1
A18: 11 | B18: P | C18: -10/ZN | D18: 43 | E18: - | F18: 1
A19: 12 | B19: P | C19: -10/ZN | D19: 43 | E19: - | F19: 1
A20: 13 | B20: P | C20: -10/ZN | D20: 39 | E20: - | F20: 1
A21: 14 | B21: P | C21: -10/ZN | D21: 39 | E21: 1 | F21: 1
A22: 15 | B22: RPK | C22: -10,5/10/E | D22: 40 | E22: - | F22: 1
A23: 15.1 | B23: N | C23: -10,5/10/E | D23: 17 | E23: - | F23: 1
A24: 15.2 | B24: K | C24: -10,5/10/E | D24: 40 | E24: - | F24: 1
A25: 16 | B25: P | C25: -10/ZN | D25: 39 | E25: - | F25: 1
A26: 17 | B26: P | C26: -10/ZN | D26: 33 | E26: - | F26: 1
A27: 18 | B27: RPKr | C27: -10/ZN | D27: 43 | E27: - | F27: 1
A28: 19 | B28: RPK | C28: -10,5/10/E | D28: 45 | E28: 1 | F28: 1
A29: 19.1 | B29: P | C29: -10/ZN | D29: 45 | E29: - | F29: 1
A30: 19.2 | B30: P | C30: -10/ZN | D30: 47 | E30: - | F30: 1
A31: 19.3 | B31: P | C31: -10/ZN | D31: 46 | E31: 1 | F31: 1
A32: 19.4 | B32: K | C32: -10,5/10/E | D32: 46 | E32: - | F32: 1
A33: 20 | B33: K | C33: -10,5/10/E | D33: 41 | E33: - | F33: 1
A34: 1 | B34: Nb | C34: -10,5/10/E | D34: 10 | E34: - | F34: 2
A35: 2 | B35: P | C35: -10/ZN | D35: 42 | E35: - | F35: 2
A36: 3 | B36: RPK | C36: -10,5/10/E | D36: 37 | E36: 1 | F36: 2
A37: 3.1 | B37: N | C37: -10,5/10/E | D37: 5 | E37: - | F37: 2
A38: 3.2 | B38: P | C38: -10/ZN | D38: 26 | E38: - | F38: 2
A39: 3.3 | B39: P | C39: -10/ZN | D39: 25 | E39: - | F39: 2
A40: 3.4 | B40: K | C40: -10,5/10/E | D40: 25 | E40: 1 | F40: 2
...
