Workbook

Sheet zestawienie
A1: stacja | B1: ilość | C1: długość | D1: kontrola
A2: 03-0494 | B2: =COUNTA('03-0494'!A:A)-1 -> 39 | C2: =SUM('03-0494'!D:D) -> 1640 | D2: 1 błędów, 2 uwag
A3: 03-0495 | B3: =COUNTA('03-0495'!A:A)-1 -> 67 | C3: =SUM('03-0495'!D:D) -> 2755 | D3: 7 błędów, 7 uwag
A4: 03-0496 | B4: =COUNTA('03-0496'!A:A)-1 -> 25 | C4: =SUM('03-0496'!D:D) -> 927 | D4: 1 uwag
A5: 03-0497 | B5: =COUNTA('03-0497'!A:A)-1 -> 8 | C5: =SUM('03-0497'!D:D) -> 285 | D5: 2 błędów, 1 uwag
A6: 03-0541 | B6: =COUNTA('03-0541'!A:A)-1 -> 11 | C6: =SUM('03-0541'!D:D) -> 380 | D6: 1 błędów
A7: 03-0664 | B7: =COUNTA('03-0664'!A:A)-1 -> 14 | C7: =SUM('03-0664'!D:D) -> 426 | D7: 2 błędów, 4 uwag
A8: 03-1233 | B8: =COUNTA('03-1233'!A:A)-1 -> 90 | C8: =SUM('03-1233'!D:D) -> 3216 | D8: 46 błędów, 16 uwag
A9: 03-1250 | B9: =COUNTA('03-1250'!A:A)-1 -> 17 | C9: =SUM('03-1250'!D:D) -> 837 | D9: 5 błędów, 15 uwag
A10: 03-1336 | B10: =COUNTA('03-1336'!A:A)-1 -> 3 | C10: =SUM('03-1336'!D:D) -> 85 | D10: OK
A11: 03-1341 | B11: =COUNTA('03-1341'!A:A)-1 -> 18 | C11: =SUM('03-1341'!D:D) -> 847 | D11: 9 błędów, 18 uwag
A12: 03-1439 | B12: =COUNTA('03-1439'!A:A)-1 -> 13 | C12: =SUM('03-1439'!D:D) -> 416 | D12: 2 błędów
A13: RAZEM | B13: =SUM(B2:B12) -> 305 | C13: =SUM(C2:C12) -> 11814 | D13: patrz arkusz "kontrola"

Sheet kontrola
A1: Poziom | B1: Stacja | C1: Obwód | D1: Nr słupa | E1: Opis | F1: X | G1: Y
A2: BŁĄD | B2: 03-0494 | C2: 1 | D2: 7 | E2: Dwa różne wymiary (53 m i 55 m) między słupem nr 7 a nr 6. | F2: 7526241.4 | G2: 5787129.8
A3: BŁĄD | B3: 03-0495 | C3: 1 | D3: 12 | E3: Brak wymiaru do słupa nr 11 - odległość 29 m zmierzona z rysunku (dorysuj wymiar). | F3: 7527013.5 | G3: 5787474.7
A4: BŁĄD | B4: 03-0495 | C4: 2 | D4: 1 | E4: Wymiar 52 m między pierwszymi słupami dwóch obwodów (nr 1 i nr 1) nie został użyty - sprawdź odległości pierwszych przęseł od stacji. | F4: 7527480.3 | G4: 5787468.3
A5: BŁĄD | B5: 03-0495 | C5: 3 | D5: 13 | E5: Brak wymiaru do słupa nr 12 - odległość ustalona przez podział wymiaru 44 m ze słupem nr 14 (dorysuj wymiar). | F5: 7527009 | G5: 5787489.5
A6: BŁĄD | B6: 03-0495 | C6: 3 | D6: 13 | E6: Numer 13 występuje 2 razy w obwodzie 3. | F6: 7527228.7 | G6: 5787143.2
A7: BŁĄD | B7: 03-0495 | C7: 3 | D7: 14 | E7: Numer 14 występuje 2 razy w obwodzie 3. | F7: 7527019 | G7: 5787532
A8: BŁĄD | B8: 03-0495 | C8: 3 | D8: 15 | E8: Wymiar 100 m między słupem nr 15 a nr 13 nie został użyty jako przęsło - numeracja nie zgadza się z wymiarami (sprawdź numery lub zaczepienie wymiaru). | F8: 7527128.2 | G8: 5787146.2
A9: BŁĄD | B9: 03-0495 | C9: 3 | D9: 17 | E9: Wymiar 97 m między słupem nr 17 a nr 15 nie został użyty jako przęsło - numeracja nie zgadza się z wymiarami (sprawdź numery lub zaczepienie wymiaru). | F9: 7527031.1 | G9: 5787148.6
A10: BŁĄD | B10: 03-0497 | C10: 1 | D10: 1 | E10: Słup nr 2 leży bliżej stacji niż słup nr 1 - numery mogą być zamienione. | F10: 7528527.4 | G10: 5787533.8
A11: BŁĄD | B11: 03-0497 | C11: 1 | D11: 7 | E11: Brak wymiaru do słupa nr 6 - odległość ustalona przez podział wymiaru 51 m ze słupem nr 8 (dorysuj wymiar). | F11: 7528856.5 | G11: 5787744.8
A12: BŁĄD | B12: 03-0541 | C12: 1 | D12: 1 | E12: Słup nr 2 leży bliżej stacji niż słup nr 1 - numery mogą być zamienione. | F12: 7525028.7 | G12: 5787766
A13: BŁĄD | B13: 03-0664 | E13: Mufa nie leży przy żadnym słupie (najbliższy 16.3 m) - nie wpisano jej. | F13: 7525132.7 | G13: 5787863.9
A14: BŁĄD | B14: 03-0664 | C14: 1 | D14: 1 | E14: Słup nr 2 leży bliżej stacji niż słup nr 1 - numery mogą być zamienione. | F14: 7524870 | G14: 5788101.2
A15: BŁĄD | B15: 03-1233 | E15: Słup N-10.5/10/E nie ma numeru - brak go w zestawieniu. | F15: 7526233.8 | G15: 5787436.6
A16: BŁĄD | B16: 03-1233 | E16: Słup RPP-10.5/10/E nie ma numeru - brak go w zestawieniu. | F16: 7526211.5 | G16: 5787468.4
A17: BŁĄD | B17: 03-1233 | E17: Mufa nie leży przy żadnym słupie (najbliższy 5.3 m) - nie wpisano jej. | F17: 7526235.7 | G17: 5787472.6
A18: BŁĄD | B18: 03-1233 | C18: 2 | D18: 5 | E18: Brak wymiaru do słupa nr 4 - odległość ustalona przez podział wymiaru 29 m ze słupem nr 6 (dorysuj wymiar). | F18: 7526192.3 | G18: 5787488
A19: BŁĄD | B19: 03-1233 | C19: 2 | D19: 5 | E19: Numer 5 występuje 2 razy w obwodzie 2. | F19: 7526192.3 | G19: 5787488
A20: BŁĄD | B20: 03-1233 | C20: 2 | D20: 6 | E20: Numer 6 występuje 2 razy w obwodzie 2. | F20: 7526536.8 | G20: 5787489.9
A21: BŁĄD | B21: 03-1233 | C21: 2 | D21: 7 | E21: Numer 7 występuje 2 razy w obwodzie 2. | F21: 7526129.4 | G21: 5787497.3
A22: BŁĄD | B22: 03-1233 | C22: 2 | D22: 8 | E22: Numer 8 występuje 2 razy w obwodzie 2. | F22: 7526093.1 | G22: 5787496.7
A23: BŁĄD | B23: 03-1233 | C23: 2 | D23: 9 | E23: Numer 9 występuje 2 razy w obwodzie 2. | F23: 7526058.4 | G23: 5787495.8
A24: BŁĄD | B24: 03-1233 | C24: 2 | D24: 10 | E24: Numer 10 występuje 2 razy w obwodzie 2. | F24: 7526018 | G24: 5787494.6
A25: BŁĄD | B25: 03-1233 | C25: 2 | D25: 11 | E25: Numer 11 występuje 2 razy w obwodzie 2. | F25: 7525975.5 | G25: 5787492.3
A26: BŁĄD | B26: 03-1233 | C26: 2 | D26: 12 | E26: Numer 12 występuje 2 razy w obwodzie 2. | F26: 7526639.1 | G26: 5787583.1
A27: BŁĄD | B27: 03-1233 | C27: 2 | D27: 13 | E27: Numer 13 występuje 2 razy w obwodzie 2. | F27: 7526646.9 | G27: 5787617.3
A28: BŁĄD | B28: 03-1233 | C28: 2 | D28: 14 | E28: Brak wymiaru do słupa nr 13 - odległość ustalona przez podział wymiaru 33 m ze słupem nr 15 (dorysuj wymiar). | F28: 7525155.8 | G28: 5787842.5
A29: BŁĄD | B29: 03-1233 | C29: 2 | D29: 14 | E29: Słup leży w zakresie stacji 03-0664, a w zestawieniu jest w stacji 03-1233. | F29: 7525155.8 | G29: 5787842.5
... A60: BŁĄD | B60: 03-1233 | C60: 3 | D60: 4.3 | E60: Brak wymiaru do słupa nr 4.2 - odległość 67 m zmierzona z rysunku (dorysuj wymiar). | F60: 7526239.7 | G60: 5787476
A61: BŁĄD | B61: 03-1250 | E61: Mufa nie leży przy żadnym słupie (najbliższy 24.9 m) - nie wpisano jej. | F61: 7525480.8 | G61: 5787019.6
A62: BŁĄD | B62: 03-1250 | C62: 2 | D62: 4 | E62: Brak wymiaru do słupa nr 3 - odległość 173 m zmierzona z rysunku (dorysuj wymiar). | F62: 7525494.3 | G62: 5787092.8
A63: BŁĄD | B63: 03-1250 | C63: 2 | D63: 4 | E63: Numer 4 występuje 2 razy w obwodzie 2. | F63: 7525494.3 | G63: 5787092.8
A64: BŁĄD | B64: 03-1250 | C64: 2 | D64: 6 | E64: Brak wymiaru do słupa nr 5 - odległość 244 m zmierzona z rysunku (dorysuj wymiar). | F64: 7525485.2 | G64: 5787044.2
A65: BŁĄD | B65: 03-1250 | C65: 2 | D65: 6 | E65: Numer 6 występuje 2 razy w obwodzie 2. | F65: 7525485.2 | G65: 5787044.2
A66: BŁĄD | B66: 03-1341 | C66: 1 | D66: 2 | E66: Brak wymiaru do słupa nr 1 - odległość 63 m zmierzona z rysunku (dorysuj wymiar). | F66: 7525422.8 | G66: 5787876.5
A67: BŁĄD | B67: 03-1341 | C67: 1 | D67: 2 | E67: Numer 2 występuje 2 razy w obwodzie 1. | F67: 7525422.8 | G67: 5787876.5
A68: BŁĄD | B68: 03-1341 | C68: 1 | D68: 4 | E68: Brak wymiaru do słupa nr 3 - odległość 183 m zmierzona z rysunku (dorysuj wymiar). | F68: 7525327.3 | G68: 5787879.3
A69: BŁĄD | B69: 03-1341 | C69: 1 | D69: 4 | E69: Numer 4 występuje 2 razy w obwodzie 1. | F69: 7525327.3 | G69: 5787879.3
A70: BŁĄD | B70: 03-1341 | C70: 1 | D70: 6 | E70: Brak wymiaru do słupa nr 5 - odległość ustalona przez podział wymiaru 18 m ze słupem nr 6.1 (dorysuj wymiar). | F70: 7525287.5 | G70: 5787880.6
...

Sheet 03-0494
A1: Nr słupa | B1: Oznaczenie | C1: Typ | D1: Odległość | E1: Mufa | F1: Obwód | G1: Kontrola
A2: 1 | B2: P | C2: -10/ZN | D2: 27 | F2: 1
A3: 2 | B3: RPKr | C3: -10/ZN | D3: 26 | F3: 1
A4: 3 | B4: P | C4: -10/ZN | D4: 47 | F4: 1
A5: 4 | B5: P | C5: -10/ZN | D5: 50 | F5: 1
A6: 5 | B6: RPKr | C6: -10/ZN | D6: 50 | E6: 1 | F6: 1
A7: 5.1 | B7: RPKr | C7: -10/ZN | D7: 49 | E7: 1 | F7: 1
A8: 5.2 | B8: P | C8: -10/ZN | D8: 52 | F8: 1
A9: 5.3 | B9: Kr | C9: -10/ZN | D9: 51 | F9: 1
A10: 5.4 | B10: N | C10: -10.5/10/E | D10: 26 | F10: 1
A11: 5.5 | B11: N | C11: -10.5/10/E | D11: 13 | F11: 1
A12: 5.6 | B12: RPK | C12: -10.5/10/E | D12: 8 | E12: 1 | F12: 1
A13: 5.7 | B13: Nr | C13: -10/ZN | D13: 52 | F13: 1
A14: 6 | B14: Nr | C14: -10/ZN | D14: 46 | F14: 1
A15: 7 | B15: P | C15: -10/ZN | D15: 53 | F15: 1 | G15: BŁĄD: Dwa różne wymiary (53 m i 55 m) między słupem nr 7 a nr 6.
A16: 8 | B16: P | C16: -10/ZN | D16: 53 | F16: 1
A17: 9 | B17: RPKr | C17: -10/ZN | D17: 49 | E17: 1 | F17: 1
A18: 10 | B18: P | C18: -10/ZN | D18: 51 | F18: 1
A19: 11 | B19: P | C19: -10/ZN | D19: 41 | F19: 1
A20: 12 | B20: P | C20: -10/ZN | D20: 44 | F20: 1
A21: 13 | B21: Nr | C21: -10/ZN | D21: 44 | E21: 1 | F21: 1
A22: 14 | B22: P | C22: -10/ZN | D22: 40 | F22: 1
A23: 15 | B23: Nr | C23: -10/ZN | D23: 42 | F23: 1
A24: 16 | B24: N | C24: -10.5/10/E | D24: 51 | E24: 1 | F24: 1
A25: 17 | B25: P | C25: -10/ZN | D25: 39 | F25: 1
A26: 18 | B26: K | C26: -10.5/10/E | D26: 37 | F26: 1
A27: 1 | B27: Nr | C27: -10/ZN | D27: 12 | E27: 1 | F27: 2
A28: 2 | B28: P | C28: -10/ZN | D28: 51 | F28: 2
A29: 3 | B29: RPKr | C29: -10/ZN | D29: 51 | E29: 1 | F29: 2
A30: 4 | B30: P | C30: -10/ZN | D30: 45 | F30: 2
A31: 5 | B31: P | C31: -10/ZN | D31: 50 | F31: 2
A32: 6 | B32: P | C32: -10/ZN | D32: 50 | E32: 1 | F32: 2
A33: 7 | B33: P | C33: -10/ZN | D33: 51 | F33: 2
A34: 8 | B34: P | C34: -10/ZN | D34: 43 | F34: 2
A35: 9 | B35: Kr | C35: -10/ZN | D35: 54 | E35: 1 | F35: 2
A36: 1 | B36: RPKr | C36: -10/ZN | D36: 12 | F36: 3 | G36: UWAGA: Nie rozpoznano opisu "obw. nr" dla tego obwodu - przyjęto obwód 3.
A37: 2 | B37: RPKr | C37: -10/ZN | D37: 37 | E37: 1 | F37: 3
A38: 3 | B38: P | C38: -10/ZN | D38: 50 | F38: 3
A39: 4 | B39: P | C39: -10/ZN | D39: 49 | F39: 3
A40: 5 | B40: K | C40: -10.5/10/E | D40: 44 | E40: 1 | F40: 3

Sheet 03-0495
A1: Nr słupa | B1: Oznaczenie | C1: Typ | D1: Odległość | E1: Mufa | F1: Obwód | G1: Kontrola
A2: 1 | B2: P | C2: -10/ZN | D2: 21 | F2: 1
A3: 2 | B3: P | C3: -10/ZN | D3: 47 | F3: 1
A4: 3 | B4: RPK | C4: -10.5/10/E | D4: 22 | E4: 1 | F4: 1
A5: 3.1 | B5: Nr | C5: -10/ZN | D5: 17 | F5: 1
A6: 3.2 | B6: P | C6: -10/ZN | D6: 42 | F6: 1
A7: 3.3 | B7: P | C7: -10/ZN | D7: 41 | F7: 1
A8: 3.4 | B8: K | C8: -10.5/10/E | D8: 46 | F8: 1
A9: 4 | B9: P | C9: -10/ZN | D9: 24 | F9: 1
A10: 5 | B10: RPKr | C10: -10/ZN | D10: 50 | E10: 1 | F10: 1
A11: 5.1 | B11: P | C11: -10/ZN | D11: 53 | F11: 1
A12: 5.2 | B12: P | C12: -10/ZN | D12: 52 | F12: 1
A13: 5.3 | B13: Nr | C13: -10/ZN | D13: 54 | E13: 1 | F13: 1
A14: 5.4 | B14: Nr | C14: -10/ZN | D14: 44 | F14: 1
A15: 5.5 | B15: P | C15: -10/ZN | D15: 46 | E15: 1 | F15: 1
A16: 5.6 | B16: P | C16: -10/ZN | D16: 54 | F16: 1
A17: 5.7 | B17: P | C17: -10/ZN | D17: 45 | F17: 1
A18: 5.8 | B18: P | C18: -10/ZN | D18: 53 | E18: 1 | F18: 1
A19: 5.9 | B19: Kr | C19: -10/ZN | D19: 57 | F19: 1 | G19: UWAGA: Wymiar 88 m łączy słup nr 5.9 (stacja 03-0495) ze słupem nr 9 (stacja 03-0494) - przęsło między stacjami, nie wliczono go do zestawienia.
A20: 6 | B20: Nr | C20: -10/ZN | D20: 53 | F20: 1
A21: 7 | B21: N | C21: -10.5/10/E | D21: 34 | F21: 1
A22: 8 | B22: P | C22: -10/ZN | D22: 42 | F22: 1
A23: 9 | B23: P | C23: -10/ZN | D23: 33 | F23: 1
A24: 10 | B24: RPK | C24: -10.5/10/E | D24: 35 | E24: 1 | F24: 1
A25: 10.1 | B25: P | C25: -10/ZN | D25: 35 | F25: 1
A26: 10.2 | B26: K | C26: -10.5/10/E | D26: 38 | F26: 1
A27: 11 | B27: P | C27: -10/ZN | D27: 40 | F27: 1 | G27: UWAGA: Wymiar 37 m: jeden koniec nie jest zaczepiony o słup (6.2 m od najbliższego) - nie użyto go. | UWAGA: Wymiar 37 m: jeden koniec nie jest zaczepiony o słup (6.2 m od najbliższego) - nie użyto go.
A28: 12 | B28: N | C28: -10.5/10/E | D28: 29 | F28: 1 | G28: BŁĄD: Brak wymiaru do słupa nr 11 - odległość 29 m zmierzona z rysunku (dorysuj wymiar).
A29: 1 | B29: P | C29: -10/ZN | D29: 16 | E29: 1 | F29: 2 | G29: BŁĄD: Wymiar 52 m między pierwszymi słupami dwóch obwodów (nr 1 i nr 1) nie został użyty - sprawdź odległości pierwszych przęseł od stacji.
A30: 2 | B30: Nr | C30: -10/ZN | D30: 15 | F30: 2
A31: 3 | B31: P | C31: -10/ZN | D31: 46 | F31: 2
A32: 4 | B32: P | C32: -10/ZN | D32: 38 | F32: 2
A33: 5 | B33: Or | C33: -10/ZN | D33: 52 | E33: 1 | F33: 2
A34: 6 | B34: RPKr | C34: -10/ZN | D34: 47 | F34: 2
A35: 7 | B35: P | C35: -10/ZN | D35: 28 | F35: 2 | G35: UWAGA: Wymiar 21 m: jeden koniec nie jest zaczepiony o słup (21.1 m od najbliższego) - nie użyto go.
A36: 1 | B36: P | C36: -10/ZN | D36: 21 | E36: 1 | F36: 3
A37: 2 | B37: P | C37: -10/ZN | D37: 33 | F37: 3
A38: 3 | B38: P | C38: -10/ZN | D38: 30 | F38: 3
A39: 4 | B39: RPKr | C39: -10/ZN | D39: 31 | F39: 3
A40: 5 | B40: P | C40: -10/ZN | D40: 53 | F40: 3
...

Sheet 03-0496
A1: Nr słupa | B1: Oznaczenie | C1: Typ | D1: Odległość | E1: Mufa | F1: Obwód | G1: Kontrola
A2: 1 | B2: P | C2: -10/ZN | D2: 24 | F2: 1
A3: 2 | B3: P | C3: -10/ZN | D3: 24 | F3: 1
A4: 3 | B4: P | C4: -10/ZN | D4: 50 | F4: 1
A5: 4 | B5: P | C5: -10/ZN | D5: 49 | F5: 1
A6: 5 | B6: P | C6: -10/ZN | D6: 50 | F6: 1
A7: 6 | B7: P | C7: -10/ZN | D7: 51 | F7: 1
A8: 7 | B8: P | C8: -10/ZN | D8: 49 | F8: 1
A9: 8 | B9: RPK | C9: -10.5/10/E | D9: 23 | E9: 1 | F9: 1
A10: 8.1 | B10: Nr | C10: -10/ZN | D10: 16 | F10: 1
A11: 8.2 | B11: K | C11: -10.5/10/E | D11: 42 | F11: 1
A12: 9 | B12: P | C12: -10/ZN | D12: 26 | F12: 1
A13: 10 | B13: P | C13: -10/ZN | D13: 43 | F13: 1
A14: 11 | B14: P | C14: -10/ZN | D14: 39 | F14: 1
A15: 12 | B15: Kr | C15: -10/ZN | D15: 37 | E15: 1 | F15: 1
A16: 1 | B16: P | C16: -10/ZN | D16: 25 | F16: 2
A17: 2 | B17: P | C17: -10/ZN | D17: 24 | F17: 2
A18: 3 | B18: RPKr | C18: -10/ZN | D18: 52 | E18: 1 | F18: 2
A19: 4 | B19: P | C19: -10/ZN | D19: 50 | F19: 2
A20: 5 | B20: RPK | C20: -10.5/10/E | D20: 24 | E20: 1 | F20: 2
A21: 5.1 | B21: P | C21: -10/ZN | D21: 17 | F21: 2
A22: 5.2 | B22: K | C22: -10.5/10/E | D22: 48 | F22: 2 | G22: UWAGA: Wymiar 40 m łączy słup nr 5.2 (stacja 03-0496) ze słupem nr 4.6 (stacja 03-1233) - przęsło między stacjami, nie wliczono go do zestawienia.
A23: 6 | B23: N | C23: -10.5/10/E | D23: 27 | F23: 2
A24: 7 | B24: P | C24: -10/ZN | D24: 50 | F24: 2
A25: 8 | B25: P | C25: -10/ZN | D25: 50 | F25: 2
A26: 9 | B26: K | C26: -10.5/10/E | D26: 37 | E26: 1 | F26: 2

Sheet 03-0497
A1: Nr słupa | B1: Oznaczenie | C1: Typ | D1: Odległość | E1: Mufa | F1: Obwód | G1: Kontrola
A2: 1 | B2: RPKr | C2: -10/ZN | D2: 27 | F2: 1 | G2: BŁĄD: Słup nr 2 leży bliżej stacji niż słup nr 1 - numery mogą być zamienione.
A3: 2 | B3: P | C3: -10/ZN | D3: 26 | F3: 1
A4: 3 | B4: RPKr | C4: -10/ZN | D4: 46 | E4: 1 | F4: 1
A5: 4 | B5: P | C5: -10/ZN | D5: 55 | F5: 1
A6: 5 | B6: N | C6: -10.5/10/E | D6: 27 | F6: 1
A7: 6 | B7: K | C7: -10.5/10/E | D7: 53 | F7: 1 | G7: UWAGA: Słup końcowy (K) ma kolejny słup nr 7 - sprawdź oznaczenie lub numerację.
A8: 7 | B8: P | C8: -10.5/10/E | D8: 25 | F8: 1 | G8: BŁĄD: Brak wymiaru do słupa nr 6 - odległość ustalona przez podział wymiaru 51 m ze słupem nr 8 (dorysuj wymiar).
A9: 8 | B9: RPK | C9: -10.5/10/E | D9: 26 | E9: 1 | F9: 1

Sheet 03-0541
A1: Nr słupa | B1: Oznaczenie | C1: Typ | D1: Odległość | E1: Mufa | F1: Obwód | G1: Kontrola
A2: 1 | B2: Nr | C2: -10/ZN | D2: 22 | E2: 1 | F2: 1 | G2: BŁĄD: Słup nr 2 leży bliżej stacji niż słup nr 1 - numery mogą być zamienione.
A3: 2 | B3: P | C3: -10/ZN | D3: 22 | F3: 1
A4: 3 | B4: P | C4: -10/ZN | D4: 48 | F4: 1
A5: 4 | B5: P | C5: -10/ZN | D5: 48 | F5: 1
A6: 5 | B6: P | C6: -10/ZN | D6: 41 | F6: 1
A7: 6 | B7: RPKr | C7: -10/ZN | D7: 32 | E7: 1 | F7: 1
A8: 7 | B8: P | C8: -10/ZN | D8: 38 | F8: 1
A9: 8 | B9: P | C9: -10/ZN | D9: 38 | F9: 1
A10: 9 | B10: P | C10: -10/ZN | D10: 22 | F10: 1
A11: 10 | B11: P | C11: -10/ZN | D11: 23 | F11: 1
A12: 11 | B12: Kr | C12: -10/ZN | D12: 46 | F12: 1

Sheet 03-0664
A1: Nr słupa | B1: Oznaczenie | C1: Typ | D1: Odległość | E1: Mufa | F1: Obwód | G1: Kontrola
A2: 1 | B2: P | C2: -10/ZN | D2: 18 | F2: 1 | G2: BŁĄD: Słup nr 2 leży bliżej stacji niż słup nr 1 - numery mogą być zamienione.
A3: 2 | B3: P | C3: -10/ZN | D3: 18 | F3: 1
A4: 3 | B4: RPKr | C4: -10/ZN | D4: 22 | F4: 1
A5: 3.1 | B5: P | C5: -10/ZN | D5: 23 | F5: 1
A6: 3.2 | B6: P | C6: -10/ZN | D6: 22 | F6: 1
A7: 3.3 | B7: Kr | C7: -10/ZN | D7: 22 | F7: 1
A8: 4 | B8: RPKr | C8: -10/ZN | D8: 23 | F8: 1
A9: 5 | B9: P | C9: -10/ZN | D9: 47 | E9: 1 | F9: 1
A10: 6 | B10: P | C10: -10/ZN | D10: 43 | F10: 1
A11: 7 | B11: P | C11: -10/ZN | D11: 41 | E11: 1 | F11: 1
A12: 8 | B12: P | C12: -10/ZN | D12: 43 | F12: 1
A13: 9 | B13: P | C13: -10/ZN | D13: 43 | E13: 1 | F13: 1
A14: 10 | B14: RPKr | C14: -10/ZN | D14: 16 | F14: 1 | G14: UWAGA: Wymiar 19 m: jeden koniec nie jest zaczepiony o słup (19.4 m od najbliższego) - nie użyto go. | UWAGA: Wymiar 19 m: jeden koniec nie jest zaczepiony o słup (19.4 m od najbliższego) - nie użyto go.
A15: 11 | B15: Kr | C15: -10/ZN | D15: 45 | F15: 1

Sheet 03-1233
A1: Nr słupa | B1: Oznaczenie | C1: Typ | D1: Odległość | E1: Mufa | F1: Obwód | G1: Kontrola
A2: 1 | B2: N | C2: -10.5/10/E | D2: 5 | F2: 1
A3: 2 | B3: RPK | C3: -10.5/10/E | D3: 22 | F3: 1
A4: 3 | B4: N | C4: -10.5/10/E | D4: 31 | F4: 1 | G4: UWAGA: Wymiar 43 m: jeden koniec nie jest zaczepiony o słup (5.3 m od najbliższego) - nie użyto go. | UWAGA: Wymiar 43 m: jeden koniec nie jest zaczepiony o słup (5.3 m od najbliższego) - nie użyto go.
A5: 1 | B5: Nb | C5: -10.5/10/E | D5: 5 | F5: 2
A6: 2 | B6: P | C6: -10/ZN | D6: 42 | F6: 2
A7: 3 | B7: RPK | C7: -10.5/10/E | D7: 37 | E7: 1 | F7: 2
A8: 3.1 | B8: N | C8: -10.5/10/E | D8: 5 | F8: 2
A9: 3.2 | B9: P | C9: -10/ZN | D9: 26 | F9: 2
A10: 3.3 | B10: P | C10: -10/ZN | D10: 25 | F10: 2
A11: 3.4 | B11: K | C11: -10.5/10/E | D11: 25 | E11: 1 | F11: 2
A12: 4 | B12: P | C12: -10/ZN | D12: 40 | F12: 2
A13: 5 | B13: P | C13: -10/ZN | D13: 14 | F13: 2 | G13: UWAGA: Wymiar 46 m: jeden koniec nie jest zaczepiony o słup (5.3 m od najbliższego) - nie użyto go. | UWAGA: Wymiar 46 m: jeden koniec nie jest zaczepiony o słup (5.3 m od najbliższego) - nie użyto go. | BŁĄD: Brak wymiaru do słupa nr 4 - odległość ustalona przez podział wymiaru 29 m ze słupem nr 6 (dorysuj wymiar). | BŁĄD: Numer 5 występuje 2 razy w obwodzie 2.
A14: 5 | B14: P | C14: -10/ZN | D14: 41 | F14: 2
A15: 6 | B15: P | C15: -10/ZN | D15: 37 | F15: 2 | G15: BŁĄD: Numer 6 występuje 2 razy w obwodzie 2.
A16: 6 | B16: N | C16: -10.5/10/E | D16: 15 | F16: 2
A17: 7 | B17: P | C17: -10/ZN | D17: 35 | E17: 1 | F17: 2 | G17: BŁĄD: Numer 7 występuje 2 razy w obwodzie 2.
A18: 7 | B18: P | C18: -10/ZN | D18: 41 | F18: 2
A19: 8 | B19: P | C19: -10/ZN | D19: 36 | F19: 2 | G19: BŁĄD: Numer 8 występuje 2 razy w obwodzie 2.
A20: 8 | B20: N | C20: -10.5/10/E | D20: 32 | F20: 2
A21: 9 | B21: P | C21: -10/ZN | D21: 35 | F21: 2 | G21: BŁĄD: Numer 9 występuje 2 razy w obwodzie 2.
A22: 9 | B22: RPK | C22: -10.5/10/E | D22: 14 | E22: 1 | F22: 2 | G22: UWAGA: Wymiar 36 m łączy słup nr 9 (stacja 03-1233) ze słupem nr 9 (stacja 03-1439) - przęsło między stacjami, nie wliczono go do zestawienia.
A23: 10 | B23: P | C23: -10/ZN | D23: 40 | E23: 1 | F23: 2 | G23: BŁĄD: Numer 10 występuje 2 razy w obwodzie 2.
A24: 10 | B24: N | C24: -10.5/10/E | D24: 5 | F24: 2
A25: 11 | B25: P | C25: -10/ZN | D25: 43 | F25: 2 | G25: BŁĄD: Numer 11 występuje 2 razy w obwodzie 2.
A26: 11 | B26: RPK | C26: -10.5/10/E | D26: 46 | E26: 1 | F26: 2
A27: 11.1 | B27: N | C27: -10.5/10/E | D27: 13 | F27: 2
A28: 11.2 | B28: N | C28: -10.5/10/E | D28: 25 | F28: 2
A29: 11.3 | B29: N | C29: -10.5/10/E | D29: 8 | F29: 2
A30: 11.4 | B30: P | C30: -10/ZN | D30: 37 | F30: 2
A31: 11.5 | B31: P | C31: -10/ZN | D31: 41 | F31: 2
A32: 11.6 | B32: P | C32: -10/ZN | D32: 41 | F32: 2
A33: 11.7 | B33: RPK | C33: -10.5/10/E | D33: 41 | E33: 1 | F33: 2
A34: 11.7.1 | B34: P | C34: -10/ZN | D34: 46 | F34: 2
A35: 11.7.2 | B35: Nr | C35: -10/ZN | D35: 50 | F35: 2
A36: 11.7.3 | B36: P | C36: -10/ZN | D36: 41 | F36: 2
A37: 11.7.4 | B37: RPK | C37: -10.5/10/E | D37: 13 | E37: 1 | F37: 2
A38: 11.7.5 | B38: P | C38: -10/ZN | D38: 37 | F38: 2
A39: 11.7.6 | B39: P | C39: -10/ZN | D39: 50 | F39: 2
A40: 11.7.7 | B40: P | C40: -10/ZN | D40: 50 | F40: 2
...

Sheet 03-1250
A1: Nr słupa | B1: Oznaczenie | C1: Typ | D1: Odległość | E1: Mufa | F1: Obwód | G1: Kontrola
A2: 1 | B2: P | C2: -10/ZN | D2: 16 | F2: 1
A3: 2 | B3: P | C3: -10/ZN | D3: 15 | E3: 1 | F3: 1 | G3: UWAGA: Wymiar 32 m: jeden koniec nie jest zaczepiony o słup (22.1 m od najbliższego) - nie użyto go. | UWAGA: Wymiar 32 m: jeden koniec nie jest zaczepiony o słup (22.1 m od najbliższego) - nie użyto go.
A4: 1 | B4: P | C4: -10/ZN | D4: 17 | F4: 2
A5: 2 | B5: P | C5: -10/ZN | D5: 16 | F5: 2
A6: 3 | B6: RPK | C6: -10.5/10/E | D6: 33 | E6: 1 | F6: 2
A7: 3.1 | B7: N | C7: -10.5/10/E | D7: 16 | F7: 2
A8: 3.2 | B8: K | C8: -10.5/10/E | D8: 35 | F8: 2
A9: 4 | B9: P | C9: -10/ZN | D9: 173 | E9: 1 | F9: 2 | G9: UWAGA: Wymiar 26 m: jeden koniec nie jest zaczepiony o słup (23.6 m od najbliższego) - nie użyto go. | UWAGA: Wymiar 22 m: jeden koniec nie jest zaczepiony o słup (22.1 m od najbliższego) - nie użyto go. | UWAGA: Wymiar 26 m: jeden koniec nie jest zaczepiony o słup (23.6 m od najbliższego) - nie użyto go. | UWAGA: Wymiar 22 m: jeden koniec nie jest zaczepiony o słup (22.1 m od najbliższego) - nie użyto go. | BŁĄD: Brak wymiaru do słupa nr 3 - odległość 173 m zmierzona z rysunku (dorysuj wymiar). | BŁĄD: Numer 4 występuje 2 razy w obwodzie 2. | UWAGA: Bardzo długie przęsło: 173 m (więcej niż 70 m).
A10: 4 | B10: P | C10: -10/ZN | D10: 35 | F10: 2
A11: 5 | B11: N | C11: -10.5/10/E | D11: 36 | E11: 1 | F11: 2
A12: 6 | B12: P | C12: -10/ZN | D12: 244 | F12: 2 | G12: UWAGA: Wymiar 25 m: jeden koniec nie jest zaczepiony o słup (25.0 m od najbliższego) - nie użyto go. | UWAGA: Wymiar 24 m: jeden koniec nie jest zaczepiony o słup (23.6 m od najbliższego) - nie użyto go. | UWAGA: Wymiar 25 m: jeden koniec nie jest zaczepiony o słup (25.0 m od najbliższego) - nie użyto go. | UWAGA: Wymiar 24 m: jeden koniec nie jest zaczepiony o słup (23.6 m od najbliższego) - nie użyto go. | BŁĄD: Brak wymiaru do słupa nr 5 - odległość 244 m zmierzona z rysunku (dorysuj wymiar). | BŁĄD: Numer 6 występuje 2 razy w obwodzie 2. | UWAGA: Bardzo długie przęsło: 244 m (więcej niż 70 m).
A13: 6 | B13: P | C13: -10/ZN | D13: 28 | F13: 2
A14: 7 | B14: RPK | C14: -10.5/10/E | D14: 37 | E14: 1 | F14: 2
A15: 8 | B15: N | C15: -10.5/10/E | D15: 22 | F15: 2
A16: 9 | B16: N | C16: -10.5/10/E | D16: 14 | F16: 2
A17: 10 | B17: P | C17: -10/ZN | D17: 46 | F17: 2
A18: 11 | B18: K | C18: -10.5/10/E | D18: 54 | E18: 1 | F18: 2

Sheet 03-1336
A1: Nr słupa | B1: Oznaczenie | C1: Typ | D1: Odległość | E1: Mufa | F1: Obwód | G1: Kontrola
A2: 1 | B2: P | C2: -10/ZN | D2: 22 | E2: 1 | F2: 1
A3: 2 | B3: P | C3: -10/ZN | D3: 21 | F3: 1
A4: 3 | B4: K | C4: -10.5/10/E | D4: 42 | F4: 1

Sheet 03-1341
A1: Nr słupa | B1: Oznaczenie | C1: Typ | D1: Odległość | E1: Mufa | F1: Obwód | G1: Kontrola
A2: 1 | B2: P | C2: -10/ZN | D2: 12 | F2: 1 | G2: UWAGA: Wymiar 21 m: jeden koniec nie jest zaczepiony o słup (20.8 m od najbliższego) - nie użyto go. | UWAGA: Wymiar 21 m: jeden koniec nie jest zaczepiony o słup (20.8 m od najbliższego) - nie użyto go.
A3: 2 | B3: P | C3: -10/ZN | D3: 63 | E3: 1 | F3: 1 | G3: UWAGA: Wymiar 45 m: jeden koniec nie jest zaczepiony o słup (45.4 m od najbliższego) - nie użyto go. | UWAGA: Wymiar 42 m: jeden koniec nie jest zaczepiony o słup (20.8 m od najbliższego) - nie użyto go. | UWAGA: Wymiar 45 m: jeden koniec nie jest zaczepiony o słup (45.4 m od najbliższego) - nie użyto go. | UWAGA: Wymiar 42 m: jeden koniec nie jest zaczepiony o słup (20.8 m od najbliższego) - nie użyto go. | BŁĄD: Brak wymiaru do słupa nr 1 - odległość 63 m zmierzona z rysunku (dorysuj wymiar). | BŁĄD: Numer 2 występuje 2 razy w obwodzie 1.
A4: 2 | B4: N | C4: -10.5/10/E | D4: 11 | E4: 1 | F4: 1
A5: 3 | B5: N | C5: -10.5/10/E | D5: 22 | F5: 1
A6: 4 | B6: P | C6: -10/ZN | D6: 183 | F6: 1 | G6: UWAGA: Wymiar 32 m: jeden koniec nie jest zaczepiony o słup (8.0 m od najbliższego) - nie użyto go. | UWAGA: Wymiar 50 m: jeden koniec nie jest zaczepiony o słup (45.4 m od najbliższego) - nie użyto go. | UWAGA: Wymiar 32 m: jeden koniec nie jest zaczepiony o słup (8.0 m od najbliższego) - nie użyto go. | UWAGA: Wymiar 50 m: jeden koniec nie jest zaczepiony o słup (45.4 m od najbliższego) - nie użyto go. | BŁĄD: Brak wymiaru do słupa nr 3 - odległość 183 m zmierzona z rysunku (dorysuj wymiar). | BŁĄD: Numer 4 występuje 2 razy w obwodzie 1. | UWAGA: Bardzo długie przęsło: 183 m (więcej niż 70 m).
A7: 4 | B7: N | C7: -10.5/10/E | D7: 23 | F7: 1
A8: 5 | B8: P | C8: -10/ZN | D8: 40 | F8: 1
A9: 6 | B9: P | C9: -10/ZN | D9: 49 | F9: 1 | G9: BŁĄD: Numer 6 występuje 2 razy w obwodzie 1.
A10: 6 | B10: RPK | C10: -10.5/10/E | D10: 9 | E10: 1 | F10: 1 | G10: UWAGA: Wymiar 8 m: jeden koniec nie jest zaczepiony o słup (8.0 m od najbliższego) - nie użyto go. | UWAGA: Wymiar 8 m: jeden koniec nie jest zaczepiony o słup (8.0 m od najbliższego) - nie użyto go. | BŁĄD: Brak wymiaru do słupa nr 5 - odległość ustalona przez podział wymiaru 18 m ze słupem nr 6.1 (dorysuj wymiar).
A11: 6.1 | B11: K | C11: -10.5/10/E | D11: 9 | F11: 1
A12: 7 | B12: P | C12: -10/ZN | D12: 49 | F12: 1 | G12: BŁĄD: Numer 7 występuje 2 razy w obwodzie 1.
A13: 7 | B13: N | C13: -10.5/10/E | D13: 29 | E13: 1 | F13: 1
A14: 8 | B14: P | C14: -10/ZN | D14: 33 | F14: 1 | G14: BŁĄD: Numer 8 występuje 2 razy w obwodzie 1.
A15: 8 | B15: P | C15: -10/ZN | D15: 26 | F15: 1
A16: 9 | B16: K | C16: -10.5/10/E | D16: 32 | F16: 1 | G16: UWAGA: Słup końcowy (K) ma kolejny słup nr 10 - sprawdź oznaczenie lub numerację.
A17: 10 | B17: RPK | C17: -10.5/10/E | D17: 169 | F17: 1 | G17: BŁĄD: Brak wymiaru do słupa nr 9 - odległość 169 m zmierzona z rysunku (dorysuj wymiar). | UWAGA: Bardzo długie przęsło: 169 m (więcej niż 70 m).
A18: 11 | B18: P | C18: -10/ZN | D18: 44 | F18: 1
A19: 12 | B19: P | C19: -10/ZN | D19: 44 | F19: 1

Sheet 03-1439
A1: Nr słupa | B1: Oznaczenie | C1: Typ | D1: Odległość | E1: Mufa | F1: Obwód | G1: Kontrola
A2: 1 | B2: K | C2: -10.5/10/E | D2: 17 | F2: 1 | G2: BŁĄD: Słup nr 2 leży bliżej stacji niż słup nr 1 - numery mogą być zamienione.
A3: 2 | B3: N | C3: -10.5/10/E | D3: 17 | F3: 1
A4: 3 | B4: P | C4: -10/ZN | D4: 46 | F4: 1 | G4: BŁĄD: Brak wymiaru do słupa nr 2 - odległość 46 m zmierzona z rysunku (dorysuj wymiar).
A5: 3.1 | B5: P | C5: -10/ZN | D5: 14 | F5: 1
A6: 4 | B6: P | C6: -10/ZN | D6: 40 | F6: 1
A7: 5 | B7: P | C7: -10/ZN | D7: 40 | E7: 1 | F7: 1
A8: 6 | B8: P | C8: -10/ZN | D8: 35 | F8: 1
A9: 7 | B9: RPKb | C9: -10/ZN | D9: 35 | E9: 1 | F9: 1
A10: 7.1 | B10: N | C10: -10.5/10/E | D10: 8 | F10: 1
A11: 7.2 | B11: P | C11: -10/ZN | D11: 46 | F11: 1
A12: 7.3 | B12: K | C12: -10.5/10/E | D12: 45 | F12: 1
A13: 8 | B13: P | C13: -10/ZN | D13: 36 | F13: 1
A14: 9 | B14: P | C14: -10/ZN | D14: 37 | F14: 1
